以下是对这段代码的详细讲解：

**一、`MyPromise`类的定义**

1. `constructor(executor)`
   - 这是构造函数，接受一个`executor`函数作为参数。`executor`函数通常有两个参数：`resolve`和`reject`，用于改变`Promise`的状态。
   - 初始化状态相关的属性：
     - `this.status = 'pending';`：初始状态为`pending`，表示`Promise`的结果尚未确定。
     - `this.value = undefined;`：成功时的值初始为`undefined`。
     - `this.reason = undefined;`：失败时的原因初始为`undefined`。
     - `this.onResolvedCallbacks = [];`：存储成功回调函数的数组。
     - `this.onRejectedCallbacks = [];`：存储失败回调函数的数组。
   - 定义`resolve`函数：
     - `const resolve = (value) => {... }`：这个函数用于将`Promise`的状态从`pending`改为`fulfilled`，并设置成功的值。如果当前状态是`pending`，则更新状态为`fulfilled`，设置`value`为传入的值，并执行所有存储在`onResolvedCallbacks`数组中的成功回调函数。
   - 定义`reject`函数：
     - `const reject = (reason) => {... }`：这个函数用于将`Promise`的状态从`pending`改为`rejected`，并设置失败的原因。如果当前状态是`pending`，则更新状态为`rejected`，设置`reason`为传入的值，并执行所有存储在`onRejectedCallbacks`数组中的失败回调函数。
   - 执行`executor`函数并处理错误：
     - `try { executor(resolve, reject); } catch (err) { reject(err); }`：立即执行传入的`executor`函数，并将`resolve`和`reject`函数作为参数传递给它。如果在执行`executor`函数过程中发生错误，直接调用`reject`函数来表示`Promise`被拒绝。

2. `then(onFulfilled, onRejected)`方法
   - 这个方法用于实现链式调用，接受两个参数：`onFulfilled`是成功时的回调函数，`onRejected`是失败时的回调函数。如果这两个参数不是函数类型，则会提供默认的行为。
   - 参数处理：
     - `onFulfilled = typeof onFulfilled === 'function'? onFulfilled : value => value;`：如果`onFulfilled`不是函数，则提供一个默认的函数，直接返回传入的值。
     - `onRejected = typeof onRejected === 'function'? onRejected : reason => { throw reason };`：如果`onRejected`不是函数，则提供一个默认的函数，直接抛出传入的原因。
   - 返回新的`Promise`：
     - `return new MyPromise((resolve, reject) => {... });`：返回一个新的`Promise`，以便实现链式调用。在这个新的`Promise`中，根据当前`Promise`的状态执行不同的逻辑。
   - 如果当前状态是`fulfilled`：
     - 在定时器中执行`onFulfilled`回调函数，并捕获可能的错误。如果没有错误，将回调函数的返回值传递给新的`Promise`的`resolve`函数，以便继续链式调用。如果有错误，将错误传递给新的`Promise`的`reject`函数。
   - 如果当前状态是`rejected`：
     - 与`fulfilled`状态类似，在定时器中执行`onRejected`回调函数，并处理可能的错误。
   - 如果当前状态是`pending`：
     - 将成功和失败的回调函数分别添加到对应的数组中。当状态改变时，这些回调函数将被执行。

3. `catch(onRejected)`方法
   - 这个方法用于捕获错误，接受一个参数`onRejected`，即失败时的回调函数。
   - 返回一个新的`Promise`，调用`then`方法并传入`null`作为成功的回调函数，将`onRejected`作为失败的回调函数，实现捕获错误的功能。

**二、测试示例**

1. 创建一个新的`Promise`对象`testPromise`：
   - `const testPromise = new MyPromise((resolve, reject) => {... });`：创建一个新的`Promise`，在`executor`函数中使用定时器模拟异步操作。在定时器结束后，调用`resolve`函数表示成功，或者调用`reject`函数表示失败。这里只调用了`resolve('Success!')`，表示成功的情况。

2. 链式调用`then`和`catch`方法：
   - `testPromise.then(value => {... })`：在`Promise`成功时执行第一个`then`方法，打印出成功的值，并返回`'Step 2'`。
   - `then(value => {... })`：在第一个`then`方法的基础上继续链式调用第二个`then`方法。这里抛出一个错误，导致`Promise`被拒绝。
   - `catch(err => {... })`：使用`catch`方法捕获前面`then`方法中抛出的错误，并打印错误信息。

总的来说，这段代码实现了一个自定义的`Promise`类，模拟了原生`Promise`的基本功能，包括异步操作的处理、状态的改变、链式调用和错误处理。测试示例展示了如何创建一个`Promise`对象，并使用`then`和`catch`方法进行链式调用和错误处理。